<?xml version="1.0"?>
<robot xmlns:xacro="http://www.ros.org/wiki/xacro" >

    <xacro:include filename="inertial_macros.xacro"/>

    <material name="white">
        <color rgba="1 1 1 1" />
    </material>

    <material name="orange">
        <color rgba="1 0.3 0.1 1" />
    </material>

    <material name="blue">
        <color rgba="0.2 0.2 1 1" />
    </material>

    <material name="black">
        <color rgba="0 0 0 1" />
    </material>

    <material name="red">
        <color rgba="1 0 0 1" />
    </material>

    <!-- BASE LINK -->
    <!--baselink will be on the axes of the drive wheels, centered between the wheels-->
    <!--the rest of the robot will be described w.r. to base_link-->
    <link name="base_link">

    </link>

    <!-- CHASSIS LINK -->

    <joint name="chassis_joint" type="fixed">
        <parent link="base_link"/>
        <child link="chassis"/>
        <!--need to adjust origin to align wheels on chassis-->
        <origin xyz="-0.04 0 0"/>
    </joint>

    <link name="chassis">
        <visual>
            <!--need to adjust origin of chassis box to align robopet wheel positions-->
            <!--need to change box geometry, collision, and inertial tags-->
            <origin xyz="0.115 0 0.075"/>
            <geometry>
                <box size="0.23 0.15 0.15"/>
            </geometry>
            <material name="white"/>
        </visual>
        <collision>
            <origin xyz="0.115 0 0.075"/>
            <geometry>
                <box size="0.23 0.15 0.15"/>
            </geometry>
        </collision>
        <xacro:inertial_box mass="0.5" x="0.23" y="0.15" z="0.15">
            <origin xyz="0.115 0 0.075" rpy="0 0 0"/>
        </xacro:inertial_box>
    </link>

    <gazebo reference="chassis">
        <material>Gazebo/White</material>
    </gazebo>

    <!-- LEFT WHEEL LINK -->

    <joint name="left_wheel_joint" type="continuous">
        <parent link="base_link"/>
        <child link="left_wheel"/>
        <!--adjust wheel joint origin to proper chassis width-->
        <origin xyz="0 0.1 0" rpy="-${pi/2} 0 0"/> 
        <axis xyz="0 0 1"/>
    </joint>

    <link name="left_wheel">
        <!--need to adjust wheel geometry and inertial properties-->
        <visual>
            <geometry>
                <cylinder radius="0.03" length="0.025"/>
            </geometry>
            <material name="blue"/>
        </visual>
        <collision>
            <geometry>
                <sphere radius="0.03"/>
            </geometry>
        </collision>
        <xacro:inertial_cylinder mass="0.1" length="0.025" radius="0.03">
            <origin xyz="0 0 0" rpy="0 0 0"/>
        </xacro:inertial_cylinder>
    </link>

    <gazebo reference="left_wheel">
        <material>Gazebo/Blue</material>
    </gazebo>

    <!-- RIGHT WHEEL LINK -->

    <joint name="right_wheel_joint" type="continuous">
        <parent link="base_link"/>
        <child link="right_wheel"/>
        <!--adjust wheel joint origin to proper chassis width-->
        <origin xyz="0 -0.1 0" rpy="${pi/2} 0 0"/>
        <axis xyz="0 0 -1"/>
    </joint>

    <link name="right_wheel">
        <!--need to adjust wheel geometry and inertial properties-->
        <visual>
            <geometry>
                <cylinder radius="0.03" length="0.025"/>
            </geometry>
            <material name="blue"/>
        </visual>
        <collision>
            <geometry>
                <sphere radius="0.03"/>
            </geometry>
        </collision>
        <xacro:inertial_cylinder mass="0.1" length="0.025" radius="0.03">
            <origin xyz="0 0 0" rpy="0 0 0"/>
        </xacro:inertial_cylinder>
    </link>

    <gazebo reference="right_wheel">
        <material>Gazebo/Blue</material>
    </gazebo>

    <!-- CASTER WHEEL LINK -->
    <!--gonna keep caster wheel as is since it doesn't change much-->

    <joint name="caster_wheel_joint" type="fixed">
        <parent link="chassis"/>
        <child link="caster_wheel"/>
        <!--may adjust origin to align it on bot-->
        <origin xyz="0.2 0 0"/>
    </joint>

    <link name="caster_wheel">
        <!--would consider adjusting radius to replicate ride height-->
        <visual>
            <geometry>
                <sphere radius="0.03"/>
            </geometry>
            <material name="black"/>
        </visual>
        <collision>
            <geometry>
                <sphere radius="0.03"/>
            </geometry>
        </collision>
        <xacro:inertial_sphere mass="0.1" radius="0.03">
            <origin xyz="0 0 0" rpy="0 0 0"/>
        </xacro:inertial_sphere>
    </link>

    <gazebo reference="caster_wheel">
        <material>Gazebo/Black</material>
        <mu1 value="0.001"/>
        <mu2 value="0.001"/>
    </gazebo>

</robot>